Oops! Assertion failed

The following assertion was not satisfied
  assert foo(1,*[2],z=3) is False, error()

Assertion values
  assert foo(1,*[2],z=3) is False, error()
                ^ is = [2]
  assert foo(1,*[2],z=3) is False, error()
         ^ is = (1, (2,), {'z': 3})
  assert foo(1,*[2],z=3) is False, error()
                         ^ is = False
  assert foo(1,*[2],z=3) is False, error()
  ^ is False

Where
  File 'tests/tests.py', line 123 in 'run'

115|  
116|                  with subsuite.test("args *args **kwargs") as test:
117|                      vs = []
118|                      def foo(x,*y,**z):
119|                          test.note((x, y, z))
120|                          vs.append((x, y, z))
121|                          return x, y, z
122|                      with raises(AssertionError) as e:
123|>                         assert foo(1,*[2],z=3) is False, error()
124|                      test.note(e.exception)
125|                      with test.test("assert args, *args, **kwargs are the same"):
126|                          assert vs[0] == vs[1]
